---------------------------------------------
SLURM job ID:        786292
SLURM job node list: gpu001
DATE:                Fri Aug 23 11:15:30 PM CEST 2024
---------------------------------------------
Traceback (most recent call last):
  File "/orfeo/cephfs/home/dssc/scandu00/nlp-env/lib64/python3.9/site-packages/huggingface_hub/utils/_errors.py", line 304, in hf_raise_for_status
    response.raise_for_status()
  File "/orfeo/cephfs/home/dssc/scandu00/nlp-env/lib64/python3.9/site-packages/requests/models.py", line 1021, in raise_for_status
    raise HTTPError(http_error_msg, response=self)
requests.exceptions.HTTPError: 401 Client Error: Unauthorized for url: https://huggingface.co/google/gemma-2b-it/resolve/main/config.json

The above exception was the direct cause of the following exception:

Traceback (most recent call last):
  File "/orfeo/cephfs/home/dssc/scandu00/nlp-env/lib64/python3.9/site-packages/transformers/utils/hub.py", line 402, in cached_file
    resolved_file = hf_hub_download(
  File "/orfeo/cephfs/home/dssc/scandu00/nlp-env/lib64/python3.9/site-packages/huggingface_hub/utils/_deprecation.py", line 101, in inner_f
    return f(*args, **kwargs)
  File "/orfeo/cephfs/home/dssc/scandu00/nlp-env/lib64/python3.9/site-packages/huggingface_hub/utils/_validators.py", line 114, in _inner_fn
    return fn(*args, **kwargs)
  File "/orfeo/cephfs/home/dssc/scandu00/nlp-env/lib64/python3.9/site-packages/huggingface_hub/file_download.py", line 1240, in hf_hub_download
    return _hf_hub_download_to_cache_dir(
  File "/orfeo/cephfs/home/dssc/scandu00/nlp-env/lib64/python3.9/site-packages/huggingface_hub/file_download.py", line 1347, in _hf_hub_download_to_cache_dir
    _raise_on_head_call_error(head_call_error, force_download, local_files_only)
  File "/orfeo/cephfs/home/dssc/scandu00/nlp-env/lib64/python3.9/site-packages/huggingface_hub/file_download.py", line 1854, in _raise_on_head_call_error
    raise head_call_error
  File "/orfeo/cephfs/home/dssc/scandu00/nlp-env/lib64/python3.9/site-packages/huggingface_hub/file_download.py", line 1751, in _get_metadata_or_catch_error
    metadata = get_hf_file_metadata(
  File "/orfeo/cephfs/home/dssc/scandu00/nlp-env/lib64/python3.9/site-packages/huggingface_hub/utils/_validators.py", line 114, in _inner_fn
    return fn(*args, **kwargs)
  File "/orfeo/cephfs/home/dssc/scandu00/nlp-env/lib64/python3.9/site-packages/huggingface_hub/file_download.py", line 1673, in get_hf_file_metadata
    r = _request_wrapper(
  File "/orfeo/cephfs/home/dssc/scandu00/nlp-env/lib64/python3.9/site-packages/huggingface_hub/file_download.py", line 376, in _request_wrapper
    response = _request_wrapper(
  File "/orfeo/cephfs/home/dssc/scandu00/nlp-env/lib64/python3.9/site-packages/huggingface_hub/file_download.py", line 400, in _request_wrapper
    hf_raise_for_status(response)
  File "/orfeo/cephfs/home/dssc/scandu00/nlp-env/lib64/python3.9/site-packages/huggingface_hub/utils/_errors.py", line 321, in hf_raise_for_status
    raise GatedRepoError(message, response) from e
huggingface_hub.utils._errors.GatedRepoError: 401 Client Error. (Request ID: Root=1-66c8fc05-1e022288693a78ab58e82dfb;adb4e265-c28a-4f1b-98ce-84bb533c0e71)

Cannot access gated repo for url https://huggingface.co/google/gemma-2b-it/resolve/main/config.json.
Access to model google/gemma-2b-it is restricted. You must be authenticated to access it.

The above exception was the direct cause of the following exception:

Traceback (most recent call last):
  File "/u/dssc/scandu00/tesi-bozze/PECoRe-wiki-3.py", line 14, in <module>
    inseq_model = inseq.load_model(
  File "/orfeo/cephfs/home/dssc/scandu00/nlp-env/lib64/python3.9/site-packages/inseq/models/__init__.py", line 47, in load_model
    return FRAMEWORKS_MAP[framework].load(model, attribution_method, **kwargs)
  File "/orfeo/cephfs/home/dssc/scandu00/nlp-env/lib64/python3.9/site-packages/inseq/models/huggingface_model.py", line 146, in load
    is_encoder_decoder = AutoConfig.from_pretrained(model, **model_kwargs).is_encoder_decoder
  File "/orfeo/cephfs/home/dssc/scandu00/nlp-env/lib64/python3.9/site-packages/transformers/models/auto/configuration_auto.py", line 972, in from_pretrained
    config_dict, unused_kwargs = PretrainedConfig.get_config_dict(pretrained_model_name_or_path, **kwargs)
  File "/orfeo/cephfs/home/dssc/scandu00/nlp-env/lib64/python3.9/site-packages/transformers/configuration_utils.py", line 632, in get_config_dict
    config_dict, kwargs = cls._get_config_dict(pretrained_model_name_or_path, **kwargs)
  File "/orfeo/cephfs/home/dssc/scandu00/nlp-env/lib64/python3.9/site-packages/transformers/configuration_utils.py", line 689, in _get_config_dict
    resolved_config_file = cached_file(
  File "/orfeo/cephfs/home/dssc/scandu00/nlp-env/lib64/python3.9/site-packages/transformers/utils/hub.py", line 420, in cached_file
    raise EnvironmentError(
OSError: You are trying to access a gated repo.
Make sure to have access to it at https://huggingface.co/google/gemma-2b-it.
401 Client Error. (Request ID: Root=1-66c8fc05-1e022288693a78ab58e82dfb;adb4e265-c28a-4f1b-98ce-84bb533c0e71)

Cannot access gated repo for url https://huggingface.co/google/gemma-2b-it/resolve/main/config.json.
Access to model google/gemma-2b-it is restricted. You must be authenticated to access it.
DONE!
